[2021-07-20 07:07:23,743] {taskinstance.py:896} INFO - Dependencies all met for <TaskInstance: autobot.qc_check 2021-07-18T07:54:25.449895+00:00 [queued]>
[2021-07-20 07:07:24,156] {taskinstance.py:896} INFO - Dependencies all met for <TaskInstance: autobot.qc_check 2021-07-18T07:54:25.449895+00:00 [queued]>
[2021-07-20 07:07:24,156] {taskinstance.py:1087} INFO - 
--------------------------------------------------------------------------------
[2021-07-20 07:07:24,156] {taskinstance.py:1088} INFO - Starting attempt 3 of 3
[2021-07-20 07:07:24,156] {taskinstance.py:1089} INFO - 
--------------------------------------------------------------------------------
[2021-07-20 07:07:24,286] {taskinstance.py:1107} INFO - Executing <Task(BranchPythonOperator): qc_check> on 2021-07-18T07:54:25.449895+00:00
[2021-07-20 07:07:24,289] {standard_task_runner.py:52} INFO - Started process 31097 to run task
[2021-07-20 07:07:24,291] {standard_task_runner.py:76} INFO - Running: ['airflow', 'tasks', 'run', 'autobot', 'qc_check', '2021-07-18T07:54:25.449895+00:00', '--job-id', '143', '--pool', 'default_pool', '--raw', '--subdir', 'DAGS_FOLDER/AutoBot.py', '--cfg-path', '/tmp/tmp59qkhdjk', '--error-file', '/tmp/tmpyuwfzb3j']
[2021-07-20 07:07:24,292] {standard_task_runner.py:77} INFO - Job 143: Subtask qc_check
[2021-07-20 07:07:25,484] {logging_mixin.py:104} INFO - Running <TaskInstance: autobot.qc_check 2021-07-18T07:54:25.449895+00:00 [running]> on host apache-airflow.us-central1-a.c.eminent-it-info.internal
[2021-07-20 07:07:26,994] {taskinstance.py:1300} INFO - Exporting the following env vars:
AIRFLOW_CTX_DAG_OWNER=airflow
AIRFLOW_CTX_DAG_ID=autobot
AIRFLOW_CTX_TASK_ID=qc_check
AIRFLOW_CTX_EXECUTION_DATE=2021-07-18T07:54:25.449895+00:00
AIRFLOW_CTX_DAG_RUN_ID=manual__2021-07-18T07:54:25.449895+00:00
[2021-07-20 07:07:26,996] {taskinstance.py:1501} ERROR - Task failed with exception
Traceback (most recent call last):
  File "/home/karuturihemanth/airflow_env/lib/python3.9/site-packages/airflow/models/taskinstance.py", line 1157, in _run_raw_task
    self._prepare_and_execute_task_with_callbacks(context, task)
  File "/home/karuturihemanth/airflow_env/lib/python3.9/site-packages/airflow/models/taskinstance.py", line 1331, in _prepare_and_execute_task_with_callbacks
    result = self._execute_task(context, task_copy)
  File "/home/karuturihemanth/airflow_env/lib/python3.9/site-packages/airflow/models/taskinstance.py", line 1361, in _execute_task
    result = task_copy.execute(context=context)
  File "/home/karuturihemanth/airflow_env/lib/python3.9/site-packages/airflow/operators/python.py", line 179, in execute
    branch = super().execute(context)
  File "/home/karuturihemanth/airflow_env/lib/python3.9/site-packages/airflow/operators/python.py", line 150, in execute
    return_value = self.execute_callable()
  File "/home/karuturihemanth/airflow_env/lib/python3.9/site-packages/airflow/operators/python.py", line 161, in execute_callable
    return self.python_callable(*self.op_args, **self.op_kwargs)
  File "/home/karuturihemanth/airflow/dags/modes/QC.py", line 13, in QC_check
    df = pd.read_csv(file_path)
  File "/home/karuturihemanth/airflow_env/lib/python3.9/site-packages/pandas/util/_decorators.py", line 311, in wrapper
    return func(*args, **kwargs)
  File "/home/karuturihemanth/airflow_env/lib/python3.9/site-packages/pandas/io/parsers/readers.py", line 586, in read_csv
    return _read(filepath_or_buffer, kwds)
  File "/home/karuturihemanth/airflow_env/lib/python3.9/site-packages/pandas/io/parsers/readers.py", line 482, in _read
    parser = TextFileReader(filepath_or_buffer, **kwds)
  File "/home/karuturihemanth/airflow_env/lib/python3.9/site-packages/pandas/io/parsers/readers.py", line 811, in __init__
    self._engine = self._make_engine(self.engine)
  File "/home/karuturihemanth/airflow_env/lib/python3.9/site-packages/pandas/io/parsers/readers.py", line 1040, in _make_engine
    return mapping[engine](self.f, **self.options)  # type: ignore[call-arg]
  File "/home/karuturihemanth/airflow_env/lib/python3.9/site-packages/pandas/io/parsers/c_parser_wrapper.py", line 51, in __init__
    self._open_handles(src, kwds)
  File "/home/karuturihemanth/airflow_env/lib/python3.9/site-packages/pandas/io/parsers/base_parser.py", line 222, in _open_handles
    self.handles = get_handle(
  File "/home/karuturihemanth/airflow_env/lib/python3.9/site-packages/pandas/io/common.py", line 701, in get_handle
    handle = open(
FileNotFoundError: [Errno 2] No such file or directory: '/home/karuturihemanth/airflow/output_data/Test_output_20_07_2021.csv'
[2021-07-20 07:07:27,004] {taskinstance.py:1544} INFO - Marking task as FAILED. dag_id=autobot, task_id=qc_check, execution_date=20210718T075425, start_date=20210720T070723, end_date=20210720T070727
[2021-07-20 07:07:27,394] {local_task_job.py:151} INFO - Task exited with return code 1
