[2021-07-19 09:05:34,002] {taskinstance.py:896} INFO - Dependencies all met for <TaskInstance: autobot.save_data 2021-07-18T07:54:25.449895+00:00 [queued]>
[2021-07-19 09:05:34,162] {taskinstance.py:896} INFO - Dependencies all met for <TaskInstance: autobot.save_data 2021-07-18T07:54:25.449895+00:00 [queued]>
[2021-07-19 09:05:34,162] {taskinstance.py:1087} INFO - 
--------------------------------------------------------------------------------
[2021-07-19 09:05:34,162] {taskinstance.py:1088} INFO - Starting attempt 3 of 3
[2021-07-19 09:05:34,162] {taskinstance.py:1089} INFO - 
--------------------------------------------------------------------------------
[2021-07-19 09:05:34,524] {taskinstance.py:1107} INFO - Executing <Task(PythonOperator): save_data> on 2021-07-18T07:54:25.449895+00:00
[2021-07-19 09:05:34,527] {standard_task_runner.py:52} INFO - Started process 2591 to run task
[2021-07-19 09:05:34,529] {standard_task_runner.py:76} INFO - Running: ['airflow', 'tasks', 'run', 'autobot', 'save_data', '2021-07-18T07:54:25.449895+00:00', '--job-id', '108', '--pool', 'default_pool', '--raw', '--subdir', 'DAGS_FOLDER/AutoBot.py', '--cfg-path', '/tmp/tmp7fewa1pl', '--error-file', '/tmp/tmps4094de2']
[2021-07-19 09:05:34,530] {standard_task_runner.py:77} INFO - Job 108: Subtask save_data
[2021-07-19 09:05:35,736] {logging_mixin.py:104} INFO - Running <TaskInstance: autobot.save_data 2021-07-18T07:54:25.449895+00:00 [running]> on host apache-airflow.us-central1-a.c.eminent-it-info.internal
[2021-07-19 09:05:37,276] {taskinstance.py:1300} INFO - Exporting the following env vars:
AIRFLOW_CTX_DAG_OWNER=airflow
AIRFLOW_CTX_DAG_ID=autobot
AIRFLOW_CTX_TASK_ID=save_data
AIRFLOW_CTX_EXECUTION_DATE=2021-07-18T07:54:25.449895+00:00
AIRFLOW_CTX_DAG_RUN_ID=manual__2021-07-18T07:54:25.449895+00:00
[2021-07-19 09:05:37,763] {taskinstance.py:1501} ERROR - Task failed with exception
Traceback (most recent call last):
  File "/home/karuturihemanth/airflow_env/lib/python3.9/site-packages/airflow/models/taskinstance.py", line 1157, in _run_raw_task
    self._prepare_and_execute_task_with_callbacks(context, task)
  File "/home/karuturihemanth/airflow_env/lib/python3.9/site-packages/airflow/models/taskinstance.py", line 1331, in _prepare_and_execute_task_with_callbacks
    result = self._execute_task(context, task_copy)
  File "/home/karuturihemanth/airflow_env/lib/python3.9/site-packages/airflow/models/taskinstance.py", line 1361, in _execute_task
    result = task_copy.execute(context=context)
  File "/home/karuturihemanth/airflow_env/lib/python3.9/site-packages/airflow/operators/python.py", line 150, in execute
    return_value = self.execute_callable()
  File "/home/karuturihemanth/airflow_env/lib/python3.9/site-packages/airflow/operators/python.py", line 161, in execute_callable
    return self.python_callable(*self.op_args, **self.op_kwargs)
  File "/home/karuturihemanth/airflow/dags/modes/report_automator.py", line 100, in save_data
    queries = eval(queries)
TypeError: eval() arg 1 must be a string, bytes or code object
[2021-07-19 09:05:37,765] {taskinstance.py:1544} INFO - Marking task as FAILED. dag_id=autobot, task_id=save_data, execution_date=20210718T075425, start_date=20210719T090534, end_date=20210719T090537
[2021-07-19 09:05:38,198] {local_task_job.py:151} INFO - Task exited with return code 1
