[2021-07-19 08:42:36,050] {taskinstance.py:896} INFO - Dependencies all met for <TaskInstance: autobot.execute_sql_script 2021-07-18T07:54:25.449895+00:00 [queued]>
[2021-07-19 08:42:36,217] {taskinstance.py:896} INFO - Dependencies all met for <TaskInstance: autobot.execute_sql_script 2021-07-18T07:54:25.449895+00:00 [queued]>
[2021-07-19 08:42:36,217] {taskinstance.py:1087} INFO - 
--------------------------------------------------------------------------------
[2021-07-19 08:42:36,217] {taskinstance.py:1088} INFO - Starting attempt 1 of 1
[2021-07-19 08:42:36,217] {taskinstance.py:1089} INFO - 
--------------------------------------------------------------------------------
[2021-07-19 08:42:36,580] {taskinstance.py:1107} INFO - Executing <Task(PythonOperator): execute_sql_script> on 2021-07-18T07:54:25.449895+00:00
[2021-07-19 08:42:36,583] {standard_task_runner.py:52} INFO - Started process 1710 to run task
[2021-07-19 08:42:36,585] {standard_task_runner.py:76} INFO - Running: ['airflow', 'tasks', 'run', 'autobot', 'execute_sql_script', '2021-07-18T07:54:25.449895+00:00', '--job-id', '90', '--pool', 'default_pool', '--raw', '--subdir', 'DAGS_FOLDER/AutoBot.py', '--cfg-path', '/tmp/tmpfft5c93n', '--error-file', '/tmp/tmppb1mtu2i']
[2021-07-19 08:42:36,586] {standard_task_runner.py:77} INFO - Job 90: Subtask execute_sql_script
[2021-07-19 08:42:37,796] {logging_mixin.py:104} INFO - Running <TaskInstance: autobot.execute_sql_script 2021-07-18T07:54:25.449895+00:00 [running]> on host apache-airflow.us-central1-a.c.eminent-it-info.internal
[2021-07-19 08:42:39,351] {taskinstance.py:1300} INFO - Exporting the following env vars:
AIRFLOW_CTX_DAG_OWNER=airflow
AIRFLOW_CTX_DAG_ID=autobot
AIRFLOW_CTX_TASK_ID=execute_sql_script
AIRFLOW_CTX_EXECUTION_DATE=2021-07-18T07:54:25.449895+00:00
AIRFLOW_CTX_DAG_RUN_ID=manual__2021-07-18T07:54:25.449895+00:00
[2021-07-19 08:42:39,546] {taskinstance.py:1501} ERROR - Task failed with exception
Traceback (most recent call last):
  File "/home/karuturihemanth/airflow_env/lib/python3.9/site-packages/airflow/models/taskinstance.py", line 1157, in _run_raw_task
    self._prepare_and_execute_task_with_callbacks(context, task)
  File "/home/karuturihemanth/airflow_env/lib/python3.9/site-packages/airflow/models/taskinstance.py", line 1331, in _prepare_and_execute_task_with_callbacks
    result = self._execute_task(context, task_copy)
  File "/home/karuturihemanth/airflow_env/lib/python3.9/site-packages/airflow/models/taskinstance.py", line 1361, in _execute_task
    result = task_copy.execute(context=context)
  File "/home/karuturihemanth/airflow_env/lib/python3.9/site-packages/airflow/operators/python.py", line 150, in execute
    return_value = self.execute_callable()
  File "/home/karuturihemanth/airflow_env/lib/python3.9/site-packages/airflow/operators/python.py", line 161, in execute_callable
    return self.python_callable(*self.op_args, **self.op_kwargs)
  File "/home/karuturihemanth/airflow/dags/modes/report_automator.py", line 66, in execute_sql_script
    fd = open(sql_script_path, 'r')
FileNotFoundError: [Errno 2] No such file or directory: '/home/karuturihemanth/airflow/scripts/sql_script.sql'
[2021-07-19 08:42:39,547] {taskinstance.py:1544} INFO - Marking task as FAILED. dag_id=autobot, task_id=execute_sql_script, execution_date=20210718T075425, start_date=20210719T084236, end_date=20210719T084239
[2021-07-19 08:42:39,971] {local_task_job.py:151} INFO - Task exited with return code 1
